Workbook

Sheet Dashboard
A1: Commercial & CRM Operations Dashboard
A2: Sales pipeline, channel efficiency, rep performance and funnel health | Data snapshot: 2026-09-01
A3: Won Revenue | C3: Open Pipeline | E3: Weighted Pipeline | G3: Win Rate | I3: Avg Won Deal | K3: Stale Open Leads | M3: Excel Model
A4: =SUM(CRM_Data!$V$2:$V$1801) -> 9775630 | C4: =SUMIFS(CRM_Data!$L$2:$L$1801,CRM_Data!$U$2:$U$1801,"Open") -> 13011200 | E4: =SUM(CRM_Data!$W$2:$W$1801) -> 7830015 | G4: =IFERROR(COUNTIF(CRM_Data!$U$2:$U$1801,"Won")/(COUNTIF(CRM_Data!$U$2:$U$1801,"Won")+COUNTIF(CRM_Data!$U$2:$U$1801,"Lost")),0) -> 0.26046176 | I4: =IFERROR(SUM(CRM_Data!$V$2:$V$1801)/COUNTIF(CRM_Data!$U$2:$U$1801,"Won"),0) -> 27079.307 | K4: =COUNTIF(CRM_Data!$Z$2:$Z$1801,"STALE") -> 358 | M4: Auditable formulas

Sheet CRM_Data
A1: Lead_ID | B1: Created_Date | C1: Owner | D1: Region | E1: Raw_Source | F1: Product_Code | G1: Industry | H1: Company_Size | I1: Deal_Stage | J1: Last_Stage_Date | K1: Close_Date | L1: Expected_Value_USD | M1: Discount_Pct | N1: Stage_Probability | O1: Lost_Reason | P1: Funnel_Level | Q1: Source_Clean | R1: Product_Name | S1: Product_Category | T1: Deal_Segment | U1: Outcome | V1: Actual_Revenue_USD | W1: Weighted_Pipeline_USD | X1: Sales_Cycle_Days | Y1: Age_Days | Z1: SLA_Flag | AA1: Created_Month | AB1: Close_Month | AC1: Created_Quarter | AD1: Lead_Score | AE1: Forecast_Category
A2: L00001 | B2: 45791 | C2: Ha Vo | D2: North | E2: Google Organic | F2: CS-CLOUD | G2: Education | H2: SMB | I2: Negotiation | J2: 46168 | L2: 25800 | M2: 0 | N2: 0.85 | P2: 5 | Q2: =IFERROR(VLOOKUP(E2,Lookups!$A$5:$B$24,2,FALSE),"Other") -> Organic Search | R2: =IFERROR(VLOOKUP(F2,Lookups!$D$5:$F$10,2,FALSE),"Unknown Product") -> Service Cloud | S2: =IFERROR(VLOOKUP(F2,Lookups!$D$5:$F$10,3,FALSE),"Unknown") -> Customer Service | T2: =IF(L2>=50000,"Enterprise",IF(L2>=20000,"Mid-Market","SMB")) -> Mid-Market | U2: =IF(I2="Closed Won","Won",IF(I2="Closed Lost","Lost","Open")) -> Open | V2: =IF(U2="Won",L2*(1-M2),0) -> 0 | W2: =IF(U2="Open",L2*N2,0) -> 21930 | X2: =IF(U2="Open","",IFERROR(K2-B2,"")) | Y2: =IF(U2="Open",Lookups!$B$2-B2,X2) -> 475 | Z2: =IF(AND(U2="Open",Y2>30),"STALE","OK") -> STALE | AA2: =TEXT(B2,"yyyy-mm") -> 2025-05 | AB2: =IF(K2="","",TEXT(K2,"yyyy-mm")) | AC2: ="Q"&ROUNDUP(MONTH(B2)/3,0)&"-"&YEAR(B2) -> Q2-2025 | AD2: =MIN(100,IF(H2="Enterprise",30,IF(H2="Mid-Market",22,14))+IF(T2="Enterprise",25,IF(T2="Mid-Market",18,10))+IF(Q2="Referral",25,IF(Q2="Organic Search",20,IF(Q2="Email",18,14)))+IF(G2="Technology",10,5)) -> 57 | AE2: =IF(U2<>"Open",U2,IF(N2>=0.8,"Commit",IF(N2>=0.5,"Best Case","Pipeline"))) -> Commit
A3: L00002 | B3: 46150 | C3: Quynh Vu | D3: North | E3: Google Ads | F3: CRM-CORE | G3: Education | H3: Mid-Market | I3: Proposal | J3: 46237 | L3: 9200 | M3: 0.05 | N3: 0.65 | P3: 4 | Q3: =IFERROR(VLOOKUP(E3,Lookups!$A$5:$B$24,2,FALSE),"Other") -> Paid Search | R3: =IFERROR(VLOOKUP(F3,Lookups!$D$5:$F$10,2,FALSE),"Unknown Product") -> NexaCRM Core | S3: =IFERROR(VLOOKUP(F3,Lookups!$D$5:$F$10,3,FALSE),"Unknown") -> CRM | T3: =IF(L3>=50000,"Enterprise",IF(L3>=20000,"Mid-Market","SMB")) -> SMB | U3: =IF(I3="Closed Won","Won",IF(I3="Closed Lost","Lost","Open")) -> Open | V3: =IF(U3="Won",L3*(1-M3),0) -> 0 | W3: =IF(U3="Open",L3*N3,0) -> 5980 | X3: =IF(U3="Open","",IFERROR(K3-B3,"")) | Y3: =IF(U3="Open",Lookups!$B$2-B3,X3) -> 116 | Z3: =IF(AND(U3="Open",Y3>30),"STALE","OK") -> STALE | AA3: =TEXT(B3,"yyyy-mm") -> 2026-05 | AB3: =IF(K3="","",TEXT(K3,"yyyy-mm")) | AC3: ="Q"&ROUNDUP(MONTH(B3)/3,0)&"-"&YEAR(B3) -> Q2-2026 | AD3: =MIN(100,IF(H3="Enterprise",30,IF(H3="Mid-Market",22,14))+IF(T3="Enterprise",25,IF(T3="Mid-Market",18,10))+IF(Q3="Referral",25,IF(Q3="Organic Search",20,IF(Q3="Email",18,14)))+IF(G3="Technology",10,5)) -> 51 | AE3: =IF(U3<>"Open",U3,IF(N3>=0.8,"Commit",IF(N3>=0.5,"Best Case","Pipeline"))) -> Best Case
A4: L00003 | B4: 46164 | C4: Chi Le | D4: South | E4: newsletter | F4: CRM-PRO | G4: Retail | H4: SMB | I4: Closed Lost | J4: 46204 | K4: 46204 | L4: 23300 | M4: 0 | N4: 0 | O4: Competitor | P4: 3 | Q4: =IFERROR(VLOOKUP(E4,Lookups!$A$5:$B$24,2,FALSE),"Other") -> Email | R4: =IFERROR(VLOOKUP(F4,Lookups!$D$5:$F$10,2,FALSE),"Unknown Product") -> NexaCRM Pro | S4: =IFERROR(VLOOKUP(F4,Lookups!$D$5:$F$10,3,FALSE),"Unknown") -> CRM | T4: =IF(L4>=50000,"Enterprise",IF(L4>=20000,"Mid-Market","SMB")) -> Mid-Market | U4: =IF(I4="Closed Won","Won",IF(I4="Closed Lost","Lost","Open")) -> Lost | V4: =IF(U4="Won",L4*(1-M4),0) -> 0 | W4: =IF(U4="Open",L4*N4,0) -> 0 | X4: =IF(U4="Open","",IFERROR(K4-B4,"")) -> 40 | Y4: =IF(U4="Open",Lookups!$B$2-B4,X4) -> 40 | Z4: =IF(AND(U4="Open",Y4>30),"STALE","OK") -> OK | AA4: =TEXT(B4,"yyyy-mm") -> 2026-05 | AB4: =IF(K4="","",TEXT(K4,"yyyy-mm")) -> 2026-07 | AC4: ="Q"&ROUNDUP(MONTH(B4)/3,0)&"-"&YEAR(B4) -> Q2-2026 | AD4: =MIN(100,IF(H4="Enterprise",30,IF(H4="Mid-Market",22,14))+IF(T4="Enterprise",25,IF(T4="Mid-Market",18,10))+IF(Q4="Referral",25,IF(Q4="Organic Search",20,IF(Q4="Email",18,14)))+IF(G4="Technology",10,5)) -> 55 | AE4: =IF(U4<>"Open",U4,IF(N4>=0.8,"Commit",IF(N4>=0.5,"Best Case","Pipeline"))) -> Lost
A5: L00004 | B5: 45697 | C5: Bao Tran | D5: South | E5: SEM - Google | F5: CRM-PRO | G5: Education | H5: SMB | I5: Closed Lost | J5: 45716 | K5: 45716 | L5: 17700 | M5: 0 | N5: 0 | O5: Competitor | P5: 2 | Q5: =IFERROR(VLOOKUP(E5,Lookups!$A$5:$B$24,2,FALSE),"Other") -> Paid Search | R5: =IFERROR(VLOOKUP(F5,Lookups!$D$5:$F$10,2,FALSE),"Unknown Product") -> NexaCRM Pro | S5: =IFERROR(VLOOKUP(F5,Lookups!$D$5:$F$10,3,FALSE),"Unknown") -> CRM | T5: =IF(L5>=50000,"Enterprise",IF(L5>=20000,"Mid-Market","SMB")) -> SMB | U5: =IF(I5="Closed Won","Won",IF(I5="Closed Lost","Lost","Open")) -> Lost | V5: =IF(U5="Won",L5*(1-M5),0) -> 0 | W5: =IF(U5="Open",L5*N5,0) -> 0 | X5: =IF(U5="Open","",IFERROR(K5-B5,"")) -> 19 | Y5: =IF(U5="Open",Lookups!$B$2-B5,X5) -> 19 | Z5: =IF(AND(U5="Open",Y5>30),"STALE","OK") -> OK | AA5: =TEXT(B5,"yyyy-mm") -> 2025-02 | AB5: =IF(K5="","",TEXT(K5,"yyyy-mm")) -> 2025-02 | AC5: ="Q"&ROUNDUP(MONTH(B5)/3,0)&"-"&YEAR(B5) -> Q1-2025 | AD5: =MIN(100,IF(H5="Enterprise",30,IF(H5="Mid-Market",22,14))+IF(T5="Enterprise",25,IF(T5="Mid-Market",18,10))+IF(Q5="Referral",25,IF(Q5="Organic Search",20,IF(Q5="Email",18,14)))+IF(G5="Technology",10,5)) -> 43 | AE5: =IF(U5<>"Open",U5,IF(N5>=0.8,"Commit",IF(N5>=0.5,"Best Case","Pipeline"))) -> Lost
A6: L00005 | B6: 45739 | C6: Chi Le | D6: South | E6: Google Organic | F6: REV-OPS | G6: Education | H6: Mid-Market | I6: Closed Lost | J6: 45786 | K6: 45786 | L6: 40300 | M6: 0 | N6: 0 | O6: Competitor | P6: 4 | Q6: =IFERROR(VLOOKUP(E6,Lookups!$A$5:$B$24,2,FALSE),"Other") -> Organic Search | R6: =IFERROR(VLOOKUP(F6,Lookups!$D$5:$F$10,2,FALSE),"Unknown Product") -> Revenue Operations Suite | S6: =IFERROR(VLOOKUP(F6,Lookups!$D$5:$F$10,3,FALSE),"Unknown") -> Revenue Ops | T6: =IF(L6>=50000,"Enterprise",IF(L6>=20000,"Mid-Market","SMB")) -> Mid-Market | U6: =IF(I6="Closed Won","Won",IF(I6="Closed Lost","Lost","Open")) -> Lost | V6: =IF(U6="Won",L6*(1-M6),0) -> 0 | W6: =IF(U6="Open",L6*N6,0) -> 0 | X6: =IF(U6="Open","",IFERROR(K6-B6,"")) -> 47 | Y6: =IF(U6="Open",Lookups!$B$2-B6,X6) -> 47 | Z6: =IF(AND(U6="Open",Y6>30),"STALE","OK") -> OK | AA6: =TEXT(B6,"yyyy-mm") -> 2025-03 | AB6: =IF(K6="","",TEXT(K6,"yyyy-mm")) -> 2025-05 | AC6: ="Q"&ROUNDUP(MONTH(B6)/3,0)&"-"&YEAR(B6) -> Q1-2025 | AD6: =MIN(100,IF(H6="Enterprise",30,IF(H6="Mid-Market",22,14))+IF(T6="Enterprise",25,IF(T6="Mid-Market",18,10))+IF(Q6="Referral",25,IF(Q6="Organic Search",20,IF(Q6="Email",18,14)))+IF(G6="Technology",10,5)) -> 65 | AE6: =IF(U6<>"Open",U6,IF(N6>=0.8,"Commit",IF(N6>=0.5,"Best Case","Pipeline"))) -> Lost
A7: L00006 | B7: 46224 | C7: An Nguyen | D7: South | E7: linkedin | F7: MKT-AUTO | G7: Healthcare | H7: SMB | I7: Qualified | J7: 46254 | L7: 10400 | M7: 0.05 | N7: 0.2 | P7: 2 | Q7: =IFERROR(VLOOKUP(E7,Lookups!$A$5:$B$24,2,FALSE),"Other") -> LinkedIn | R7: =IFERROR(VLOOKUP(F7,Lookups!$D$5:$F$10,2,FALSE),"Unknown Product") -> Marketing Automation | S7: =IFERROR(VLOOKUP(F7,Lookups!$D$5:$F$10,3,FALSE),"Unknown") -> Marketing | T7: =IF(L7>=50000,"Enterprise",IF(L7>=20000,"Mid-Market","SMB")) -> SMB | U7: =IF(I7="Closed Won","Won",IF(I7="Closed Lost","Lost","Open")) -> Open | V7: =IF(U7="Won",L7*(1-M7),0) -> 0 | W7: =IF(U7="Open",L7*N7,0) -> 2080 | X7: =IF(U7="Open","",IFERROR(K7-B7,"")) | Y7: =IF(U7="Open",Lookups!$B$2-B7,X7) -> 42 | Z7: =IF(AND(U7="Open",Y7>30),"STALE","OK") -> STALE | AA7: =TEXT(B7,"yyyy-mm") -> 2026-07 | AB7: =IF(K7="","",TEXT(K7,"yyyy-mm")) | AC7: ="Q"&ROUNDUP(MONTH(B7)/3,0)&"-"&YEAR(B7) -> Q3-2026 | AD7: =MIN(100,IF(H7="Enterprise",30,IF(H7="Mid-Market",22,14))+IF(T7="Enterprise",25,IF(T7="Mid-Market",18,10))+IF(Q7="Referral",25,IF(Q7="Organic Search",20,IF(Q7="Email",18,14)))+IF(G7="Technology",10,5)) -> 43 | AE7: =IF(U7<>"Open",U7,IF(N7>=0.8,"Commit",IF(N7>=0.5,"Best Case","Pipeline"))) -> Pipeline
A8: L00007 | B8: 45952 | C8: Chi Le | D8: South | E8: Webinar | F8: CRM-CORE | G8: Manufacturing | H8: Mid-Market | I8: Closed Won | J8: 45977 | K8: 45977 | L8: 16700 | M8: 0 | N8: 1 | P8: 6 | Q8: =IFERROR(VLOOKUP(E8,Lookups!$A$5:$B$24,2,FALSE),"Other") -> Webinar | R8: =IFERROR(VLOOKUP(F8,Lookups!$D$5:$F$10,2,FALSE),"Unknown Product") -> NexaCRM Core | S8: =IFERROR(VLOOKUP(F8,Lookups!$D$5:$F$10,3,FALSE),"Unknown") -> CRM | T8: =IF(L8>=50000,"Enterprise",IF(L8>=20000,"Mid-Market","SMB")) -> SMB | U8: =IF(I8="Closed Won","Won",IF(I8="Closed Lost","Lost","Open")) -> Won | V8: =IF(U8="Won",L8*(1-M8),0) -> 16700 | W8: =IF(U8="Open",L8*N8,0) -> 0 | X8: =IF(U8="Open","",IFERROR(K8-B8,"")) -> 25 | Y8: =IF(U8="Open",Lookups!$B$2-B8,X8) -> 25 | Z8: =IF(AND(U8="Open",Y8>30),"STALE","OK") -> OK | AA8: =TEXT(B8,"yyyy-mm") -> 2025-10 | AB8: =IF(K8="","",TEXT(K8,"yyyy-mm")) -> 2025-11 | AC8: ="Q"&ROUNDUP(MONTH(B8)/3,0)&"-"&YEAR(B8) -> Q4-2025 | AD8: =MIN(100,IF(H8="Enterprise",30,IF(H8="Mid-Market",22,14))+IF(T8="Enterprise",25,IF(T8="Mid-Market",18,10))+IF(Q8="Referral",25,IF(Q8="Organic Search",20,IF(Q8="Email",18,14)))+IF(G8="Technology",10,5)) -> 51 | AE8: =IF(U8<>"Open",U8,IF(N8>=0.8,"Commit",IF(N8>=0.5,"Best Case","Pipeline"))) -> Won
A9: L00008 | B9: 45762 | C9: Quynh Vu | D9: North | E9: SEM - Google | F9: MKT-AUTO | G9: Manufacturing | H9: Mid-Market | I9: Closed Lost | J9: 45786 | K9: 45786 | L9: 33600 | M9: 0 | N9: 0 | O9: No Decision | P9: 4 | Q9: =IFERROR(VLOOKUP(E9,Lookups!$A$5:$B$24,2,FALSE),"Other") -> Paid Search | R9: =IFERROR(VLOOKUP(F9,Lookups!$D$5:$F$10,2,FALSE),"Unknown Product") -> Marketing Automation | S9: =IFERROR(VLOOKUP(F9,Lookups!$D$5:$F$10,3,FALSE),"Unknown") -> Marketing | T9: =IF(L9>=50000,"Enterprise",IF(L9>=20000,"Mid-Market","SMB")) -> Mid-Market | U9: =IF(I9="Closed Won","Won",IF(I9="Closed Lost","Lost","Open")) -> Lost | V9: =IF(U9="Won",L9*(1-M9),0) -> 0 | W9: =IF(U9="Open",L9*N9,0) -> 0 | X9: =IF(U9="Open","",IFERROR(K9-B9,"")) -> 24 | Y9: =IF(U9="Open",Lookups!$B$2-B9,X9) -> 24 | Z9: =IF(AND(U9="Open",Y9>30),"STALE","OK") -> OK | AA9: =TEXT(B9,"yyyy-mm") -> 2025-04 | AB9: =IF(K9="","",TEXT(K9,"yyyy-mm")) -> 2025-05 | AC9: ="Q"&ROUNDUP(MONTH(B9)/3,0)&"-"&YEAR(B9) -> Q2-2025 | AD9: =MIN(100,IF(H9="Enterprise",30,IF(H9="Mid-Market",22,14))+IF(T9="Enterprise",25,IF(T9="Mid-Market",18,10))+IF(Q9="Referral",25,IF(Q9="Organic Search",20,IF(Q9="Email",18,14)))+IF(G9="Technology",10,5)) -> 59 | AE9: =IF(U9<>"Open",U9,IF(N9>=0.8,"Commit",IF(N9>=0.5,"Best Case","Pipeline"))) -> Lost
A10: L00009 | B10: 45803 | C10: Quynh Vu | D10: North | E10: Webinar | F10: CS-CLOUD | G10: Education | H10: Mid-Market | I10: Closed Lost | J10: 45843 | K10: 45843 | L10: 23100 | M10: 0 | N10: 0 | O10: Price | P10: 3 | Q10: =IFERROR(VLOOKUP(E10,Lookups!$A$5:$B$24,2,FALSE),"Other") -> Webinar | R10: =IFERROR(VLOOKUP(F10,Lookups!$D$5:$F$10,2,FALSE),"Unknown Product") -> Service Cloud | S10: =IFERROR(VLOOKUP(F10,Lookups!$D$5:$F$10,3,FALSE),"Unknown") -> Customer Service | T10: =IF(L10>=50000,"Enterprise",IF(L10>=20000,"Mid-Market","SMB")) -> Mid-Market | U10: =IF(I10="Closed Won","Won",IF(I10="Closed Lost","Lost","Open")) -> Lost | V10: =IF(U10="Won",L10*(1-M10),0) -> 0 | W10: =IF(U10="Open",L10*N10,0) -> 0 | X10: =IF(U10="Open","",IFERROR(K10-B10,"")) -> 40 | Y10: =IF(U10="Open",Lookups!$B$2-B10,X10) -> 40 | Z10: =IF(AND(U10="Open",Y10>30),"STALE","OK") -> OK | AA10: =TEXT(B10,"yyyy-mm") -> 2025-05 | AB10: =IF(K10="","",TEXT(K10,"yyyy-mm")) -> 2025-07 | AC10: ="Q"&ROUNDUP(MONTH(B10)/3,0)&"-"&YEAR(B10) -> Q2-2025 | AD10: =MIN(100,IF(H10="Enterprise",30,IF(H10="Mid-Market",22,14))+IF(T10="Enterprise",25,IF(T10="Mid-Market",18,10))+IF(Q10="Referral",25,IF(Q10="Organic Search",20,IF(Q10="Email",18,14)))+IF(G10="Technology",10,5)) -> 59 | AE10: =IF(U10<>"Open",U10,IF(N10>=0.8,"Commit",IF(N10>=0.5,"Best Case","Pipeline"))) -> Lost
A11: L00010 | B11: 45950 | C11: Ha Vo | D11: North | E11: organic search | F11: CS-CLOUD | G11: Healthcare | H11: Enterprise | I11: Negotiation | J11: 46070 | L11: 65200 | M11: 0.03 | N11: 0.85 | P11: 5 | Q11: =IFERROR(VLOOKUP(E11,Lookups!$A$5:$B$24,2,FALSE),"Other") -> Organic Search | R11: =IFERROR(VLOOKUP(F11,Lookups!$D$5:$F$10,2,FALSE),"Unknown Product") -> Service Cloud | S11: =IFERROR(VLOOKUP(F11,Lookups!$D$5:$F$10,3,FALSE),"Unknown") -> Customer Service | T11: =IF(L11>=50000,"Enterprise",IF(L11>=20000,"Mid-Market","SMB")) -> Enterprise | U11: =IF(I11="Closed Won","Won",IF(I11="Closed Lost","Lost","Open")) -> Open | V11: =IF(U11="Won",L11*(1-M11),0) -> 0 | W11: =IF(U11="Open",L11*N11,0) -> 55420 | X11: =IF(U11="Open","",IFERROR(K11-B11,"")) | Y11: =IF(U11="Open",Lookups!$B$2-B11,X11) -> 316 | Z11: =IF(AND(U11="Open",Y11>30),"STALE","OK") -> STALE | AA11: =TEXT(B11,"yyyy-mm") -> 2025-10 | AB11: =IF(K11="","",TEXT(K11,"yyyy-mm")) | AC11: ="Q"&ROUNDUP(MONTH(B11)/3,0)&"-"&YEAR(B11) -> Q4-2025 | AD11: =MIN(100,IF(H11="Enterprise",30,IF(H11="Mid-Market",22,14))+IF(T11="Enterprise",25,IF(T11="Mid-Market",18,10))+IF(Q11="Referral",25,IF(Q11="Organic Search",20,IF(Q11="Email",18,14)))+IF(G11="Technology",10,5)) -> 80 | AE11: =IF(U11<>"Open",U11,IF(N11>=0.8,"Commit",IF(N11>=0.5,"Best Case","Pipeline"))) -> Commit
A12: L00011 | B12: 46101 | C12: Tuan Bui | D12: Central | E12: Unknown Event | F12: CS-CLOUD | G12: Education | H12: Mid-Market | I12: Closed Won | J12: 46151 | K12: 46151 | L12: 42000 | M12: 0.12 | N12: 1 | P12: 6 | Q12: =IFERROR(VLOOKUP(E12,Lookups!$A$5:$B$24,2,FALSE),"Other") -> Other | R12: =IFERROR(VLOOKUP(F12,Lookups!$D$5:$F$10,2,FALSE),"Unknown Product") -> Service Cloud | S12: =IFERROR(VLOOKUP(F12,Lookups!$D$5:$F$10,3,FALSE),"Unknown") -> Customer Service | T12: =IF(L12>=50000,"Enterprise",IF(L12>=20000,"Mid-Market","SMB")) -> Mid-Market | U12: =IF(I12="Closed Won","Won",IF(I12="Closed Lost","Lost","Open")) -> Won | V12: =IF(U12="Won",L12*(1-M12),0) -> 36960 | W12: =IF(U12="Open",L12*N12,0) -> 0 | X12: =IF(U12="Open","",IFERROR(K12-B12,"")) -> 50 | Y12: =IF(U12="Open",Lookups!$B$2-B12,X12) -> 50 | Z12: =IF(AND(U12="Open",Y12>30),"STALE","OK") -> OK | AA12: =TEXT(B12,"yyyy-mm") -> 2026-03 | AB12: =IF(K12="","",TEXT(K12,"yyyy-mm")) -> 2026-05 | AC12: ="Q"&ROUNDUP(MONTH(B12)/3,0)&"-"&YEAR(B12) -> Q1-2026 | AD12: =MIN(100,IF(H12="Enterprise",30,IF(H12="Mid-Market",22,14))+IF(T12="Enterprise",25,IF(T12="Mid-Market",18,10))+IF(Q12="Referral",25,IF(Q12="Organic Search",20,IF(Q12="Email",18,14)))+IF(G12="Technology",10,5)) -> 59 | AE12: =IF(U12<>"Open",U12,IF(N12>=0.8,"Commit",IF(N12>=0.5,"Best Case","Pipeline"))) -> Won
A13: L00012 | B13: 45677 | C13: Duy Pham | D13: South | E13: organic search | F13: MKT-AUTO | G13: Education | H13: SMB | I13: Closed Lost | J13: 45716 | K13: 45716 | L13: 15700 | M13: 0 | N13: 0 | O13: Competitor | P13: 5 | Q13: =IFERROR(VLOOKUP(E13,Lookups!$A$5:$B$24,2,FALSE),"Other") -> Organic Search | R13: =IFERROR(VLOOKUP(F13,Lookups!$D$5:$F$10,2,FALSE),"Unknown Product") -> Marketing Automation | S13: =IFERROR(VLOOKUP(F13,Lookups!$D$5:$F$10,3,FALSE),"Unknown") -> Marketing | T13: =IF(L13>=50000,"Enterprise",IF(L13>=20000,"Mid-Market","SMB")) -> SMB | U13: =IF(I13="Closed Won","Won",IF(I13="Closed Lost","Lost","Open")) -> Lost | V13: =IF(U13="Won",L13*(1-M13),0) -> 0 | W13: =IF(U13="Open",L13*N13,0) -> 0 | X13: =IF(U13="Open","",IFERROR(K13-B13,"")) -> 39 | Y13: =IF(U13="Open",Lookups!$B$2-B13,X13) -> 39 | Z13: =IF(AND(U13="Open",Y13>30),"STALE","OK") -> OK | AA13: =TEXT(B13,"yyyy-mm") -> 2025-01 | AB13: =IF(K13="","",TEXT(K13,"yyyy-mm")) -> 2025-02 | AC13: ="Q"&ROUNDUP(MONTH(B13)/3,0)&"-"&YEAR(B13) -> Q1-2025 | AD13: =MIN(100,IF(H13="Enterprise",30,IF(H13="Mid-Market",22,14))+IF(T13="Enterprise",25,IF(T13="Mid-Market",18,10))+IF(Q13="Referral",25,IF(Q13="Organic Search",20,IF(Q13="Email",18,14)))+IF(G13="Technology",10,5)) -> 49 | AE13: =IF(U13<>"Open",U13,IF(N13>=0.8,"Commit",IF(N13>=0.5,"Best Case","Pipeline"))) -> Lost
A14: L00013 | B14: 45715 | C14: An Nguyen | D14: South | E14: virtual event | F14: CS-CLOUD | G14: Education | H14: Mid-Market | I14: Closed Lost | J14: 45758 | K14: 45758 | L14: 34400 | M14: 0 | N14: 0 | O14: Price | P14: 3 | Q14: =IFERROR(VLOOKUP(E14,Lookups!$A$5:$B$24,2,FALSE),"Other") -> Webinar | R14: =IFERROR(VLOOKUP(F14,Lookups!$D$5:$F$10,2,FALSE),"Unknown Product") -> Service Cloud | S14: =IFERROR(VLOOKUP(F14,Lookups!$D$5:$F$10,3,FALSE),"Unknown") -> Customer Service | T14: =IF(L14>=50000,"Enterprise",IF(L14>=20000,"Mid-Market","SMB")) -> Mid-Market | U14: =IF(I14="Closed Won","Won",IF(I14="Closed Lost","Lost","Open")) -> Lost | V14: =IF(U14="Won",L14*(1-M14),0) -> 0 | W14: =IF(U14="Open",L14*N14,0) -> 0 | X14: =IF(U14="Open","",IFERROR(K14-B14,"")) -> 43 | Y14: =IF(U14="Open",Lookups!$B$2-B14,X14) -> 43 | Z14: =IF(AND(U14="Open",Y14>30),"STALE","OK") -> OK | AA14: =TEXT(B14,"yyyy-mm") -> 2025-02 | AB14: =IF(K14="","",TEXT(K14,"yyyy-mm")) -> 2025-04 | AC14: ="Q"&ROUNDUP(MONTH(B14)/3,0)&"-"&YEAR(B14) -> Q1-2025 | AD14: =MIN(100,IF(H14="Enterprise",30,IF(H14="Mid-Market",22,14))+IF(T14="Enterprise",25,IF(T14="Mid-Market",18,10))+IF(Q14="Referral",25,IF(Q14="Organic Search",20,IF(Q14="Email",18,14)))+IF(G14="Technology",10,5)) -> 59 | AE14: =IF(U14<>"Open",U14,IF(N14>=0.8,"Commit",IF(N14>=0.5,"Best Case","Pipeline"))) -> Lost
A15: L00014 | B15: 45696 | C15: Bao Tran | D15: South | E15: Webinar | F15: CRM-CORE | G15: Financial Services | H15: SMB | I15: Negotiation | J15: 46172 | L15: 4800 | M15: 0.05 | N15: 0.85 | P15: 5 | Q15: =IFERROR(VLOOKUP(E15,Lookups!$A$5:$B$24,2,FALSE),"Other") -> Webinar | R15: =IFERROR(VLOOKUP(F15,Lookups!$D$5:$F$10,2,FALSE),"Unknown Product") -> NexaCRM Core | S15: =IFERROR(VLOOKUP(F15,Lookups!$D$5:$F$10,3,FALSE),"Unknown") -> CRM | T15: =IF(L15>=50000,"Enterprise",IF(L15>=20000,"Mid-Market","SMB")) -> SMB | U15: =IF(I15="Closed Won","Won",IF(I15="Closed Lost","Lost","Open")) -> Open | V15: =IF(U15="Won",L15*(1-M15),0) -> 0 | W15: =IF(U15="Open",L15*N15,0) -> 4080 | X15: =IF(U15="Open","",IFERROR(K15-B15,"")) | Y15: =IF(U15="Open",Lookups!$B$2-B15,X15) -> 570 | Z15: =IF(AND(U15="Open",Y15>30),"STALE","OK") -> STALE | AA15: =TEXT(B15,"yyyy-mm") -> 2025-02 | AB15: =IF(K15="","",TEXT(K15,"yyyy-mm")) | AC15: ="Q"&ROUNDUP(MONTH(B15)/3,0)&"-"&YEAR(B15) -> Q1-2025 | AD15: =MIN(100,IF(H15="Enterprise",30,IF(H15="Mid-Market",22,14))+IF(T15="Enterprise",25,IF(T15="Mid-Market",18,10))+IF(Q15="Referral",25,IF(Q15="Organic Search",20,IF(Q15="Email",18,14)))+IF(G15="Technology",10,5)) -> 43 | AE15: =IF(U15<>"Open",U15,IF(N15>=0.8,"Commit",IF(N15>=0.5,"Best Case","Pipeline"))) -> Commit
A16: L00015 | B16: 45955 | C16: Quynh Vu | D16: North | E16: LI Ads | F16: CRM-CORE | G16: Education | H16: Mid-Market | I16: Closed Lost | J16: 45987 | K16: 45987 | L16: 13400 | M16: 0 | N16: 0 | O16: No Decision | P16: 2 | Q16: =IFERROR(VLOOKUP(E16,Lookups!$A$5:$B$24,2,FALSE),"Other") -> LinkedIn | R16: =IFERROR(VLOOKUP(F16,Lookups!$D$5:$F$10,2,FALSE),"Unknown Product") -> NexaCRM Core | S16: =IFERROR(VLOOKUP(F16,Lookups!$D$5:$F$10,3,FALSE),"Unknown") -> CRM | T16: =IF(L16>=50000,"Enterprise",IF(L16>=20000,"Mid-Market","SMB")) -> SMB | U16: =IF(I16="Closed Won","Won",IF(I16="Closed Lost","Lost","Open")) -> Lost | V16: =IF(U16="Won",L16*(1-M16),0) -> 0 | W16: =IF(U16="Open",L16*N16,0) -> 0 | X16: =IF(U16="Open","",IFERROR(K16-B16,"")) -> 32 | Y16: =IF(U16="Open",Lookups!$B$2-B16,X16) -> 32 | Z16: =IF(AND(U16="Open",Y16>30),"STALE","OK") -> OK | AA16: =TEXT(B16,"yyyy-mm") -> 2025-10 | AB16: =IF(K16="","",TEXT(K16,"yyyy-mm")) -> 2025-11 | AC16: ="Q"&ROUNDUP(MONTH(B16)/3,0)&"-"&YEAR(B16) -> Q4-2025 | AD16: =MIN(100,IF(H16="Enterprise",30,IF(H16="Mid-Market",22,14))+IF(T16="Enterprise",25,IF(T16="Mid-Market",18,10))+IF(Q16="Referral",25,IF(Q16="Organic Search",20,IF(Q16="Email",18,14)))+IF(G16="Technology",10,5)) -> 51 | AE16: =IF(U16<>"Open",U16,IF(N16>=0.8,"Commit",IF(N16>=0.5,"Best Case","Pipeline"))) -> Lost
A17: L00016 | B17: 46057 | C17: Tuan Bui | D17: Central | E17: Cold Email | F17: CRM-PRO | G17: Professional Services | H17: SMB | I17: Closed Lost | J17: 46101 | K17: 46101 | L17: 23800 | M17: 0 | N17: 0 | O17: Competitor | P17: 4 | Q17: =IFERROR(VLOOKUP(E17,Lookups!$A$5:$B$24,2,FALSE),"Other") -> Outbound | R17: =IFERROR(VLOOKUP(F17,Lookups!$D$5:$F$10,2,FALSE),"Unknown Product") -> NexaCRM Pro | S17: =IFERROR(VLOOKUP(F17,Lookups!$D$5:$F$10,3,FALSE),"Unknown") -> CRM | T17: =IF(L17>=50000,"Enterprise",IF(L17>=20000,"Mid-Market","SMB")) -> Mid-Market | U17: =IF(I17="Closed Won","Won",IF(I17="Closed Lost","Lost","Open")) -> Lost | V17: =IF(U17="Won",L17*(1-M17),0) -> 0 | W17: =IF(U17="Open",L17*N17,0) -> 0 | X17: =IF(U17="Open","",IFERROR(K17-B17,"")) -> 44 | Y17: =IF(U17="Open",Lookups!$B$2-B17,X17) -> 44 | Z17: =IF(AND(U17="Open",Y17>30),"STALE","OK") -> OK | AA17: =TEXT(B17,"yyyy-mm") -> 2026-02 | AB17: =IF(K17="","",TEXT(K17,"yyyy-mm")) -> 2026-03 | AC17: ="Q"&ROUNDUP(MONTH(B17)/3,0)&"-"&YEAR(B17) -> Q1-2026 | AD17: =MIN(100,IF(H17="Enterprise",30,IF(H17="Mid-Market",22,14))+IF(T17="Enterprise",25,IF(T17="Mid-Market",18,10))+IF(Q17="Referral",25,IF(Q17="Organic Search",20,IF(Q17="Email",18,14)))+IF(G17="Technology",10,5)) -> 51 | AE17: =IF(U17<>"Open",U17,IF(N17>=0.8,"Commit",IF(N17>=0.5,"Best Case","Pipeline"))) -> Lost
A18: L00017 | B18: 45897 | C18: Chi Le | D18: South | E18: Webinar | F18: CRM-CORE | G18: Retail | H18: SMB | I18: Negotiation | J18: 46135 | L18: 7500 | M18: 0 | N18: 0.85 | P18: 5 | Q18: =IFERROR(VLOOKUP(E18,Lookups!$A$5:$B$24,2,FALSE),"Other") -> Webinar | R18: =IFERROR(VLOOKUP(F18,Lookups!$D$5:$F$10,2,FALSE),"Unknown Product") -> NexaCRM Core | S18: =IFERROR(VLOOKUP(F18,Lookups!$D$5:$F$10,3,FALSE),"Unknown") -> CRM | T18: =IF(L18>=50000,"Enterprise",IF(L18>=20000,"Mid-Market","SMB")) -> SMB | U18: =IF(I18="Closed Won","Won",IF(I18="Closed Lost","Lost","Open")) -> Open | V18: =IF(U18="Won",L18*(1-M18),0) -> 0 | W18: =IF(U18="Open",L18*N18,0) -> 6375 | X18: =IF(U18="Open","",IFERROR(K18-B18,"")) | Y18: =IF(U18="Open",Lookups!$B$2-B18,X18) -> 369 | Z18: =IF(AND(U18="Open",Y18>30),"STALE","OK") -> STALE | AA18: =TEXT(B18,"yyyy-mm") -> 2025-08 | AB18: =IF(K18="","",TEXT(K18,"yyyy-mm")) | AC18: ="Q"&ROUNDUP(MONTH(B18)/3,0)&"-"&YEAR(B18) -> Q3-2025 | AD18: =MIN(100,IF(H18="Enterprise",30,IF(H18="Mid-Market",22,14))+IF(T18="Enterprise",25,IF(T18="Mid-Market",18,10))+IF(Q18="Referral",25,IF(Q18="Organic Search",20,IF(Q18="Email",18,14)))+IF(G18="Technology",10,5)) -> 43 | AE18: =IF(U18<>"Open",U18,IF(N18>=0.8,"Commit",IF(N18>=0.5,"Best Case","Pipeline"))) -> Commit
A19: L00018 | B19: 46192 | C19: Quynh Vu | D19: North | E19: Cold Email | F19: REV-OPS | G19: Financial Services | H19: Mid-Market | I19: Closed Lost | J19: 46231 | K19: 46231 | L19: 80200 | M19: 0 | N19: 0 | O19: Timing | P19: 3 | Q19: =IFERROR(VLOOKUP(E19,Lookups!$A$5:$B$24,2,FALSE),"Other") -> Outbound | R19: =IFERROR(VLOOKUP(F19,Lookups!$D$5:$F$10,2,FALSE),"Unknown Product") -> Revenue Operations Suite | S19: =IFERROR(VLOOKUP(F19,Lookups!$D$5:$F$10,3,FALSE),"Unknown") -> Revenue Ops | T19: =IF(L19>=50000,"Enterprise",IF(L19>=20000,"Mid-Market","SMB")) -> Enterprise | U19: =IF(I19="Closed Won","Won",IF(I19="Closed Lost","Lost","Open")) -> Lost | V19: =IF(U19="Won",L19*(1-M19),0) -> 0 | W19: =IF(U19="Open",L19*N19,0) -> 0 | X19: =IF(U19="Open","",IFERROR(K19-B19,"")) -> 39 | Y19: =IF(U19="Open",Lookups!$B$2-B19,X19) -> 39 | Z19: =IF(AND(U19="Open",Y19>30),"STALE","OK") -> OK | AA19: =TEXT(B19,"yyyy-mm") -> 2026-06 | AB19: =IF(K19="","",TEXT(K19,"yyyy-mm")) -> 2026-07 | AC19: ="Q"&ROUNDUP(MONTH(B19)/3,0)&"-"&YEAR(B19) -> Q2-2026 | AD19: =MIN(100,IF(H19="Enterprise",30,IF(H19="Mid-Market",22,14))+IF(T19="Enterprise",25,IF(T19="Mid-Market",18,10))+IF(Q19="Referral",25,IF(Q19="Organic Search",20,IF(Q19="Email",18,14)))+IF(G19="Technology",10,5)) -> 66 | AE19: =IF(U19<>"Open",U19,IF(N19>=0.8,"Commit",IF(N19>=0.5,"Best Case","Pipeline"))) -> Lost
A20: L00019 | B20: 46191 | C20: Tuan Bui | D20: Central | E20: Offline List | F20: MKT-AUTO | G20: Retail | H20: Mid-Market | I20: Demo / Meeting | J20: 46229 | L20: 17200 | M20: 0.05 | N20: 0.4 | P20: 3 | Q20: =IFERROR(VLOOKUP(E20,Lookups!$A$5:$B$24,2,FALSE),"Other") -> Other | R20: =IFERROR(VLOOKUP(F20,Lookups!$D$5:$F$10,2,FALSE),"Unknown Product") -> Marketing Automation | S20: =IFERROR(VLOOKUP(F20,Lookups!$D$5:$F$10,3,FALSE),"Unknown") -> Marketing | T20: =IF(L20>=50000,"Enterprise",IF(L20>=20000,"Mid-Market","SMB")) -> SMB | U20: =IF(I20="Closed Won","Won",IF(I20="Closed Lost","Lost","Open")) -> Open | V20: =IF(U20="Won",L20*(1-M20),0) -> 0 | W20: =IF(U20="Open",L20*N20,0) -> 6880 | X20: =IF(U20="Open","",IFERROR(K20-B20,"")) | Y20: =IF(U20="Open",Lookups!$B$2-B20,X20) -> 75 | Z20: =IF(AND(U20="Open",Y20>30),"STALE","OK") -> STALE | AA20: =TEXT(B20,"yyyy-mm") -> 2026-06 | AB20: =IF(K20="","",TEXT(K20,"yyyy-mm")) | AC20: ="Q"&ROUNDUP(MONTH(B20)/3,0)&"-"&YEAR(B20) -> Q2-2026 | AD20: =MIN(100,IF(H20="Enterprise",30,IF(H20="Mid-Market",22,14))+IF(T20="Enterprise",25,IF(T20="Mid-Market",18,10))+IF(Q20="Referral",25,IF(Q20="Organic Search",20,IF(Q20="Email",18,14)))+IF(G20="Technology",10,5)) -> 51 | AE20: =IF(U20<>"Open",U20,IF(N20>=0.8,"Commit",IF(N20>=0.5,"Best Case","Pipeline"))) -> Pipeline
A21: L00020 | B21: 45689 | C21: Duy Pham | D21: South | E21: Referral | F21: CRM-PRO | G21: Manufacturing | H21: Mid-Market | I21: Closed Won | J21: 45712 | K21: 45712 | L21: 43800 | M21: 0.08 | N21: 1 | P21: 6 | Q21: =IFERROR(VLOOKUP(E21,Lookups!$A$5:$B$24,2,FALSE),"Other") -> Referral | R21: =IFERROR(VLOOKUP(F21,Lookups!$D$5:$F$10,2,FALSE),"Unknown Product") -> NexaCRM Pro | S21: =IFERROR(VLOOKUP(F21,Lookups!$D$5:$F$10,3,FALSE),"Unknown") -> CRM | T21: =IF(L21>=50000,"Enterprise",IF(L21>=20000,"Mid-Market","SMB")) -> Mid-Market | U21: =IF(I21="Closed Won","Won",IF(I21="Closed Lost","Lost","Open")) -> Won | V21: =IF(U21="Won",L21*(1-M21),0) -> 40296 | W21: =IF(U21="Open",L21*N21,0) -> 0 | X21: =IF(U21="Open","",IFERROR(K21-B21,"")) -> 23 | Y21: =IF(U21="Open",Lookups!$B$2-B21,X21) -> 23 | Z21: =IF(AND(U21="Open",Y21>30),"STALE","OK") -> OK | AA21: =TEXT(B21,"yyyy-mm") -> 2025-02 | AB21: =IF(K21="","",TEXT(K21,"yyyy-mm")) -> 2025-02 | AC21: ="Q"&ROUNDUP(MONTH(B21)/3,0)&"-"&YEAR(B21) -> Q1-2025 | AD21: =MIN(100,IF(H21="Enterprise",30,IF(H21="Mid-Market",22,14))+IF(T21="Enterprise",25,IF(T21="Mid-Market",18,10))+IF(Q21="Referral",25,IF(Q21="Organic Search",20,IF(Q21="Email",18,14)))+IF(G21="Technology",10,5)) -> 70 | AE21: =IF(U21<>"Open",U21,IF(N21>=0.8,"Commit",IF(N21>=0.5,"Best Case","Pipeline"))) -> Won
A22: L00021 | B22: 45753 | C22: Duy Pham | D22: South | E22: Outbound | F22: CRM-CORE | G22: Financial Services | H22: SMB | I22: Closed Lost | J22: 45775 | K22: 45775 | L22: 8800 | M22: 0 | N22: 0 | O22: Feature Gap | P22: 4 | Q22: =IFERROR(VLOOKUP(E22,Lookups!$A$5:$B$24,2,FALSE),"Other") -> Outbound | R22: =IFERROR(VLOOKUP(F22,Lookups!$D$5:$F$10,2,FALSE),"Unknown Product") -> NexaCRM Core | S22: =IFERROR(VLOOKUP(F22,Lookups!$D$5:$F$10,3,FALSE),"Unknown") -> CRM | T22: =IF(L22>=50000,"Enterprise",IF(L22>=20000,"Mid-Market","SMB")) -> SMB | U22: =IF(I22="Closed Won","Won",IF(I22="Closed Lost","Lost","Open")) -> Lost | V22: =IF(U22="Won",L22*(1-M22),0) -> 0 | W22: =IF(U22="Open",L22*N22,0) -> 0 | X22: =IF(U22="Open","",IFERROR(K22-B22,"")) -> 22 | Y22: =IF(U22="Open",Lookups!$B$2-B22,X22) -> 22 | Z22: =IF(AND(U22="Open",Y22>30),"STALE","OK") -> OK | AA22: =TEXT(B22,"yyyy-mm") -> 2025-04 | AB22: =IF(K22="","",TEXT(K22,"yyyy-mm")) -> 2025-04 | AC22: ="Q"&ROUNDUP(MONTH(B22)/3,0)&"-"&YEAR(B22) -> Q2-2025 | AD22: =MIN(100,IF(H22="Enterprise",30,IF(H22="Mid-Market",22,14))+IF(T22="Enterprise",25,IF(T22="Mid-Market",18,10))+IF(Q22="Referral",25,IF(Q22="Organic Search",20,IF(Q22="Email",18,14)))+IF(G22="Technology",10,5)) -> 43 | AE22: =IF(U22<>"Open",U22,IF(N22>=0.8,"Commit",IF(N22>=0.5,"Best Case","Pipeline"))) -> Lost
A23: L00022 | B23: 46178 | C23: Bao Tran | D23: South | E23: Google Ads | F23: CRM-CORE | G23: Technology | H23: Mid-Market | I23: Closed Won | J23: 46217 | K23: 46217 | L23: 9100 | M23: 0.05 | N23: 1 | P23: 6 | Q23: =IFERROR(VLOOKUP(E23,Lookups!$A$5:$B$24,2,FALSE),"Other") -> Paid Search | R23: =IFERROR(VLOOKUP(F23,Lookups!$D$5:$F$10,2,FALSE),"Unknown Product") -> NexaCRM Core | S23: =IFERROR(VLOOKUP(F23,Lookups!$D$5:$F$10,3,FALSE),"Unknown") -> CRM | T23: =IF(L23>=50000,"Enterprise",IF(L23>=20000,"Mid-Market","SMB")) -> SMB | U23: =IF(I23="Closed Won","Won",IF(I23="Closed Lost","Lost","Open")) -> Won | V23: =IF(U23="Won",L23*(1-M23),0) -> 8645 | W23: =IF(U23="Open",L23*N23,0) -> 0 | X23: =IF(U23="Open","",IFERROR(K23-B23,"")) -> 39 | Y23: =IF(U23="Open",Lookups!$B$2-B23,X23) -> 39 | Z23: =IF(AND(U23="Open",Y23>30),"STALE","OK") -> OK | AA23: =TEXT(B23,"yyyy-mm") -> 2026-06 | AB23: =IF(K23="","",TEXT(K23,"yyyy-mm")) -> 2026-07 | AC23: ="Q"&ROUNDUP(MONTH(B23)/3,0)&"-"&YEAR(B23) -> Q2-2026 | AD23: =MIN(100,IF(H23="Enterprise",30,IF(H23="Mid-Market",22,14))+IF(T23="Enterprise",25,IF(T23="Mid-Market",18,10))+IF(Q23="Referral",25,IF(Q23="Organic Search",20,IF(Q23="Email",18,14)))+IF(G23="Technology",10,5)) -> 56 | AE23: =IF(U23<>"Open",U23,IF(N23>=0.8,"Commit",IF(N23>=0.5,"Best Case","Pipeline"))) -> Won
A24: L00023 | B24: 45816 | C24: Quynh Vu | D24: North | E24: Referral | F24: CRM-CORE | G24: Education | H24: Enterprise | I24: Closed Lost | J24: 45835 | K24: 45835 | L24: 17400 | M24: 0 | N24: 0 | O24: Competitor | P24: 5 | Q24: =IFERROR(VLOOKUP(E24,Lookups!$A$5:$B$24,2,FALSE),"Other") -> Referral | R24: =IFERROR(VLOOKUP(F24,Lookups!$D$5:$F$10,2,FALSE),"Unknown Product") -> NexaCRM Core | S24: =IFERROR(VLOOKUP(F24,Lookups!$D$5:$F$10,3,FALSE),"Unknown") -> CRM | T24: =IF(L24>=50000,"Enterprise",IF(L24>=20000,"Mid-Market","SMB")) -> SMB | U24: =IF(I24="Closed Won","Won",IF(I24="Closed Lost","Lost","Open")) -> Lost | V24: =IF(U24="Won",L24*(1-M24),0) -> 0 | W24: =IF(U24="Open",L24*N24,0) -> 0 | X24: =IF(U24="Open","",IFERROR(K24-B24,"")) -> 19 | Y24: =IF(U24="Open",Lookups!$B$2-B24,X24) -> 19 | Z24: =IF(AND(U24="Open",Y24>30),"STALE","OK") -> OK | AA24: =TEXT(B24,"yyyy-mm") -> 2025-06 | AB24: =IF(K24="","",TEXT(K24,"yyyy-mm")) -> 2025-06 | AC24: ="Q"&ROUNDUP(MONTH(B24)/3,0)&"-"&YEAR(B24) -> Q2-2025 | AD24: =MIN(100,IF(H24="Enterprise",30,IF(H24="Mid-Market",22,14))+IF(T24="Enterprise",25,IF(T24="Mid-Market",18,10))+IF(Q24="Referral",25,IF(Q24="Organic Search",20,IF(Q24="Email",18,14)))+IF(G24="Technology",10,5)) -> 70 | AE24: =IF(U24<>"Open",U24,IF(N24>=0.8,"Commit",IF(N24>=0.5,"Best Case","Pipeline"))) -> Lost
A25: L00024 | B25: 45856 | C25: Bao Tran | D25: South | E25: SDR Outreach | F25: MKT-AUTO | G25: Manufacturing | H25: Mid-Market | I25: Closed Lost | J25: 45864 | K25: 45864 | L25: 19200 | M25: 0 | N25: 0 | O25: Budget | P25: 4 | Q25: =IFERROR(VLOOKUP(E25,Lookups!$A$5:$B$24,2,FALSE),"Other") -> Outbound | R25: =IFERROR(VLOOKUP(F25,Lookups!$D$5:$F$10,2,FALSE),"Unknown Product") -> Marketing Automation | S25: =IFERROR(VLOOKUP(F25,Lookups!$D$5:$F$10,3,FALSE),"Unknown") -> Marketing | T25: =IF(L25>=50000,"Enterprise",IF(L25>=20000,"Mid-Market","SMB")) -> SMB | U25: =IF(I25="Closed Won","Won",IF(I25="Closed Lost","Lost","Open")) -> Lost | V25: =IF(U25="Won",L25*(1-M25),0) -> 0 | W25: =IF(U25="Open",L25*N25,0) -> 0 | X25: =IF(U25="Open","",IFERROR(K25-B25,"")) -> 8 | Y25: =IF(U25="Open",Lookups!$B$2-B25,X25) -> 8 | Z25: =IF(AND(U25="Open",Y25>30),"STALE","OK") -> OK | AA25: =TEXT(B25,"yyyy-mm") -> 2025-07 | AB25: =IF(K25="","",TEXT(K25,"yyyy-mm")) -> 2025-07 | AC25: ="Q"&ROUNDUP(MONTH(B25)/3,0)&"-"&YEAR(B25) -> Q3-2025 | AD25: =MIN(100,IF(H25="Enterprise",30,IF(H25="Mid-Market",22,14))+IF(T25="Enterprise",25,IF(T25="Mid-Market",18,10))+IF(Q25="Referral",25,IF(Q25="Organic Search",20,IF(Q25="Email",18,14)))+IF(G25="Technology",10,5)) -> 51 | AE25: =IF(U25<>"Open",U25,IF(N25>=0.8,"Commit",IF(N25>=0.5,"Best Case","Pipeline"))) -> Lost
A26: L00025 | B26: 45707 | C26: An Nguyen | D26: South | E26: linkedin | F26: CS-CLOUD | G26: Retail | H26: SMB | I26: Negotiation | J26: 46185 | L26: 22400 | M26: 0 | N26: 0.85 | P26: 5 | Q26: =IFERROR(VLOOKUP(E26,Lookups!$A$5:$B$24,2,FALSE),"Other") -> LinkedIn | R26: =IFERROR(VLOOKUP(F26,Lookups!$D$5:$F$10,2,FALSE),"Unknown Product") -> Service Cloud | S26: =IFERROR(VLOOKUP(F26,Lookups!$D$5:$F$10,3,FALSE),"Unknown") -> Customer Service | T26: =IF(L26>=50000,"Enterprise",IF(L26>=20000,"Mid-Market","SMB")) -> Mid-Market | U26: =IF(I26="Closed Won","Won",IF(I26="Closed Lost","Lost","Open")) -> Open | V26: =IF(U26="Won",L26*(1-M26),0) -> 0 | W26: =IF(U26="Open",L26*N26,0) -> 19040 | X26: =IF(U26="Open","",IFERROR(K26-B26,"")) | Y26: =IF(U26="Open",Lookups!$B$2-B26,X26) -> 559 | Z26: =IF(AND(U26="Open",Y26>30),"STALE","OK") -> STALE | AA26: =TEXT(B26,"yyyy-mm") -> 2025-02 | AB26: =IF(K26="","",TEXT(K26,"yyyy-mm")) | AC26: ="Q"&ROUNDUP(MONTH(B26)/3,0)&"-"&YEAR(B26) -> Q1-2025 | AD26: =MIN(100,IF(H26="Enterprise",30,IF(H26="Mid-Market",22,14))+IF(T26="Enterprise",25,IF(T26="Mid-Market",18,10))+IF(Q26="Referral",25,IF(Q26="Organic Search",20,IF(Q26="Email",18,14)))+IF(G26="Technology",10,5)) -> 51 | AE26: =IF(U26<>"Open",U26,IF(N26>=0.8,"Commit",IF(N26>=0.5,"Best Case","Pipeline"))) -> Commit
A27: L00026 | B27: 46139 | C27: An Nguyen | D27: South | E27: customer referral | F27: CRM-PRO | G27: Professional Services | H27: Enterprise | I27: Negotiation | J27: 46188 | L27: 81700 | M27: 0 | N27: 0.85 | P27: 5 | Q27: =IFERROR(VLOOKUP(E27,Lookups!$A$5:$B$24,2,FALSE),"Other") -> Referral | R27: =IFERROR(VLOOKUP(F27,Lookups!$D$5:$F$10,2,FALSE),"Unknown Product") -> NexaCRM Pro | S27: =IFERROR(VLOOKUP(F27,Lookups!$D$5:$F$10,3,FALSE),"Unknown") -> CRM | T27: =IF(L27>=50000,"Enterprise",IF(L27>=20000,"Mid-Market","SMB")) -> Enterprise | U27: =IF(I27="Closed Won","Won",IF(I27="Closed Lost","Lost","Open")) -> Open | V27: =IF(U27="Won",L27*(1-M27),0) -> 0 | W27: =IF(U27="Open",L27*N27,0) -> 69445 | X27: =IF(U27="Open","",IFERROR(K27-B27,"")) | Y27: =IF(U27="Open",Lookups!$B$2-B27,X27) -> 127 | Z27: =IF(AND(U27="Open",Y27>30),"STALE","OK") -> STALE | AA27: =TEXT(B27,"yyyy-mm") -> 2026-04 | AB27: =IF(K27="","",TEXT(K27,"yyyy-mm")) | AC27: ="Q"&ROUNDUP(MONTH(B27)/3,0)&"-"&YEAR(B27) -> Q2-2026 | AD27: =MIN(100,IF(H27="Enterprise",30,IF(H27="Mid-Market",22,14))+IF(T27="Enterprise",25,IF(T27="Mid-Market",18,10))+IF(Q27="Referral",25,IF(Q27="Organic Search",20,IF(Q27="Email",18,14)))+IF(G27="Technology",10,5)) -> 85 | AE27: =IF(U27<>"Open",U27,IF(N27>=0.8,"Commit",IF(N27>=0.5,"Best Case","Pipeline"))) -> Commit
A28: L00027 | B28: 46110 | C28: Tuan Bui | D28: Central | E28: virtual event | F28: CS-CLOUD | G28: Manufacturing | H28: Mid-Market | I28: Closed Lost | J28: 46118 | K28: 46118 | L28: 49100 | M28: 0 | N28: 0 | O28: Price | P28: 2 | Q28: =IFERROR(VLOOKUP(E28,Lookups!$A$5:$B$24,2,FALSE),"Other") -> Webinar | R28: =IFERROR(VLOOKUP(F28,Lookups!$D$5:$F$10,2,FALSE),"Unknown Product") -> Service Cloud | S28: =IFERROR(VLOOKUP(F28,Lookups!$D$5:$F$10,3,FALSE),"Unknown") -> Customer Service | T28: =IF(L28>=50000,"Enterprise",IF(L28>=20000,"Mid-Market","SMB")) -> Mid-Market | U28: =IF(I28="Closed Won","Won",IF(I28="Closed Lost","Lost","Open")) -> Lost | V28: =IF(U28="Won",L28*(1-M28),0) -> 0 | W28: =IF(U28="Open",L28*N28,0) -> 0 | X28: =IF(U28="Open","",IFERROR(K28-B28,"")) -> 8 | Y28: =IF(U28="Open",Lookups!$B$2-B28,X28) -> 8 | Z28: =IF(AND(U28="Open",Y28>30),"STALE","OK") -> OK | AA28: =TEXT(B28,"yyyy-mm") -> 2026-03 | AB28: =IF(K28="","",TEXT(K28,"yyyy-mm")) -> 2026-04 | AC28: ="Q"&ROUNDUP(MONTH(B28)/3,0)&"-"&YEAR(B28) -> Q1-2026 | AD28: =MIN(100,IF(H28="Enterprise",30,IF(H28="Mid-Market",22,14))+IF(T28="Enterprise",25,IF(T28="Mid-Market",18,10))+IF(Q28="Referral",25,IF(Q28="Organic Search",20,IF(Q28="Email",18,14)))+IF(G28="Technology",10,5)) -> 59 | AE28: =IF(U28<>"Open",U28,IF(N28>=0.8,"Commit",IF(N28>=0.5,"Best Case","Pipeline"))) -> Lost
A29: L00028 | B29: 45911 | C29: Ha Vo | D29: North | E29: LI Ads | F29: MKT-AUTO | G29: Retail | H29: Mid-Market | I29: Closed Lost | J29: 45961 | K29: 45961 | L29: 22500 | M29: 0 | N29: 0 | O29: Competitor | P29: 5 | Q29: =IFERROR(VLOOKUP(E29,Lookups!$A$5:$B$24,2,FALSE),"Other") -> LinkedIn | R29: =IFERROR(VLOOKUP(F29,Lookups!$D$5:$F$10,2,FALSE),"Unknown Product") -> Marketing Automation | S29: =IFERROR(VLOOKUP(F29,Lookups!$D$5:$F$10,3,FALSE),"Unknown") -> Marketing | T29: =IF(L29>=50000,"Enterprise",IF(L29>=20000,"Mid-Market","SMB")) -> Mid-Market | U29: =IF(I29="Closed Won","Won",IF(I29="Closed Lost","Lost","Open")) -> Lost | V29: =IF(U29="Won",L29*(1-M29),0) -> 0 | W29: =IF(U29="Open",L29*N29,0) -> 0 | X29: =IF(U29="Open","",IFERROR(K29-B29,"")) -> 50 | Y29: =IF(U29="Open",Lookups!$B$2-B29,X29) -> 50 | Z29: =IF(AND(U29="Open",Y29>30),"STALE","OK") -> OK | AA29: =TEXT(B29,"yyyy-mm") -> 2025-09 | AB29: =IF(K29="","",TEXT(K29,"yyyy-mm")) -> 2025-10 | AC29: ="Q"&ROUNDUP(MONTH(B29)/3,0)&"-"&YEAR(B29) -> Q3-2025 | AD29: =MIN(100,IF(H29="Enterprise",30,IF(H29="Mid-Market",22,14))+IF(T29="Enterprise",25,IF(T29="Mid-Market",18,10))+IF(Q29="Referral",25,IF(Q29="Organic Search",20,IF(Q29="Email",18,14)))+IF(G29="Technology",10,5)) -> 59 | AE29: =IF(U29<>"Open",U29,IF(N29>=0.8,"Commit",IF(N29>=0.5,"Best Case","Pipeline"))) -> Lost
A30: L00029 | B30: 45963 | C30: An Nguyen | D30: South | E30: email nurture | F30: CRM-CORE | G30: Professional Services | H30: Mid-Market | I30: Closed Lost | J30: 46011 | K30: 46011 | L30: 8400 | M30: 0 | N30: 0 | O30: Price | P30: 3 | Q30: =IFERROR(VLOOKUP(E30,Lookups!$A$5:$B$24,2,FALSE),"Other") -> Email | R30: =IFERROR(VLOOKUP(F30,Lookups!$D$5:$F$10,2,FALSE),"Unknown Product") -> NexaCRM Core | S30: =IFERROR(VLOOKUP(F30,Lookups!$D$5:$F$10,3,FALSE),"Unknown") -> CRM | T30: =IF(L30>=50000,"Enterprise",IF(L30>=20000,"Mid-Market","SMB")) -> SMB | U30: =IF(I30="Closed Won","Won",IF(I30="Closed Lost","Lost","Open")) -> Lost | V30: =IF(U30="Won",L30*(1-M30),0) -> 0 | W30: =IF(U30="Open",L30*N30,0) -> 0 | X30: =IF(U30="Open","",IFERROR(K30-B30,"")) -> 48 | Y30: =IF(U30="Open",Lookups!$B$2-B30,X30) -> 48 | Z30: =IF(AND(U30="Open",Y30>30),"STALE","OK") -> OK | AA30: =TEXT(B30,"yyyy-mm") -> 2025-11 | AB30: =IF(K30="","",TEXT(K30,"yyyy-mm")) -> 2025-12 | AC30: ="Q"&ROUNDUP(MONTH(B30)/3,0)&"-"&YEAR(B30) -> Q4-2025 | AD30: =MIN(100,IF(H30="Enterprise",30,IF(H30="Mid-Market",22,14))+IF(T30="Enterprise",25,IF(T30="Mid-Market",18,10))+IF(Q30="Referral",25,IF(Q30="Organic Search",20,IF(Q30="Email",18,14)))+IF(G30="Technology",10,5)) -> 55 | AE30: =IF(U30<>"Open",U30,IF(N30>=0.8,"Commit",IF(N30>=0.5,"Best Case","Pipeline"))) -> Lost
A31: L00030 | B31: 46247 | C31: Quynh Vu | D31: North | E31: linkedin | F31: CRM-PRO | G31: Manufacturing | H31: Enterprise | I31: Qualified | J31: 46258 | L31: 80900 | M31: 0 | N31: 0.2 | P31: 2 | Q31: =IFERROR(VLOOKUP(E31,Lookups!$A$5:$B$24,2,FALSE),"Other") -> LinkedIn | R31: =IFERROR(VLOOKUP(F31,Lookups!$D$5:$F$10,2,FALSE),"Unknown Product") -> NexaCRM Pro | S31: =IFERROR(VLOOKUP(F31,Lookups!$D$5:$F$10,3,FALSE),"Unknown") -> CRM | T31: =IF(L31>=50000,"Enterprise",IF(L31>=20000,"Mid-Market","SMB")) -> Enterprise | U31: =IF(I31="Closed Won","Won",IF(I31="Closed Lost","Lost","Open")) -> Open | V31: =IF(U31="Won",L31*(1-M31),0) -> 0 | W31: =IF(U31="Open",L31*N31,0) -> 16180 | X31: =IF(U31="Open","",IFERROR(K31-B31,"")) | Y31: =IF(U31="Open",Lookups!$B$2-B31,X31) -> 19 | Z31: =IF(AND(U31="Open",Y31>30),"STALE","OK") -> OK | AA31: =TEXT(B31,"yyyy-mm") -> 2026-08 | AB31: =IF(K31="","",TEXT(K31,"yyyy-mm")) | AC31: ="Q"&ROUNDUP(MONTH(B31)/3,0)&"-"&YEAR(B31) -> Q3-2026 | AD31: =MIN(100,IF(H31="Enterprise",30,IF(H31="Mid-Market",22,14))+IF(T31="Enterprise",25,IF(T31="Mid-Market",18,10))+IF(Q31="Referral",25,IF(Q31="Organic Search",20,IF(Q31="Email",18,14)))+IF(G31="Technology",10,5)) -> 74 | AE31: =IF(U31<>"Open",U31,IF(N31>=0.8,"Commit",IF(N31>=0.5,"Best Case","Pipeline"))) -> Pipeline
A32: L00031 | B32: 45988 | C32: Duy Pham | D32: South | E32: email nurture | F32: MKT-AUTO | G32: Professional Services | H32: Mid-Market | I32: Closed Lost | J32: 46029 | K32: 46029 | L32: 21200 | M32: 0 | N32: 0 | O32: Timing | P32: 2 | Q32: =IFERROR(VLOOKUP(E32,Lookups!$A$5:$B$24,2,FALSE),"Other") -> Email | R32: =IFERROR(VLOOKUP(F32,Lookups!$D$5:$F$10,2,FALSE),"Unknown Product") -> Marketing Automation | S32: =IFERROR(VLOOKUP(F32,Lookups!$D$5:$F$10,3,FALSE),"Unknown") -> Marketing | T32: =IF(L32>=50000,"Enterprise",IF(L32>=20000,"Mid-Market","SMB")) -> Mid-Market | U32: =IF(I32="Closed Won","Won",IF(I32="Closed Lost","Lost","Open")) -> Lost | V32: =IF(U32="Won",L32*(1-M32),0) -> 0 | W32: =IF(U32="Open",L32*N32,0) -> 0 | X32: =IF(U32="Open","",IFERROR(K32-B32,"")) -> 41 | Y32: =IF(U32="Open",Lookups!$B$2-B32,X32) -> 41 | Z32: =IF(AND(U32="Open",Y32>30),"STALE","OK") -> OK | AA32: =TEXT(B32,"yyyy-mm") -> 2025-11 | AB32: =IF(K32="","",TEXT(K32,"yyyy-mm")) -> 2026-01 | AC32: ="Q"&ROUNDUP(MONTH(B32)/3,0)&"-"&YEAR(B32) -> Q4-2025 | AD32: =MIN(100,IF(H32="Enterprise",30,IF(H32="Mid-Market",22,14))+IF(T32="Enterprise",25,IF(T32="Mid-Market",18,10))+IF(Q32="Referral",25,IF(Q32="Organic Search",20,IF(Q32="Email",18,14)))+IF(G32="Technology",10,5)) -> 63 | AE32: =IF(U32<>"Open",U32,IF(N32>=0.8,"Commit",IF(N32>=0.5,"Best Case","Pipeline"))) -> Lost
A33: L00032 | B33: 46006 | C33: Ha Vo | D33: North | E33: google cpc | F33: CRM-CORE | G33: Professional Services | H33: Enterprise | I33: Negotiation | J33: 46185 | L33: 26900 | M33: 0.03 | N33: 0.85 | P33: 5 | Q33: =IFERROR(VLOOKUP(E33,Lookups!$A$5:$B$24,2,FALSE),"Other") -> Paid Search | R33: =IFERROR(VLOOKUP(F33,Lookups!$D$5:$F$10,2,FALSE),"Unknown Product") -> NexaCRM Core | S33: =IFERROR(VLOOKUP(F33,Lookups!$D$5:$F$10,3,FALSE),"Unknown") -> CRM | T33: =IF(L33>=50000,"Enterprise",IF(L33>=20000,"Mid-Market","SMB")) -> Mid-Market | U33: =IF(I33="Closed Won","Won",IF(I33="Closed Lost","Lost","Open")) -> Open | V33: =IF(U33="Won",L33*(1-M33),0) -> 0 | W33: =IF(U33="Open",L33*N33,0) -> 22865 | X33: =IF(U33="Open","",IFERROR(K33-B33,"")) | Y33: =IF(U33="Open",Lookups!$B$2-B33,X33) -> 260 | Z33: =IF(AND(U33="Open",Y33>30),"STALE","OK") -> STALE | AA33: =TEXT(B33,"yyyy-mm") -> 2025-12 | AB33: =IF(K33="","",TEXT(K33,"yyyy-mm")) | AC33: ="Q"&ROUNDUP(MONTH(B33)/3,0)&"-"&YEAR(B33) -> Q4-2025 | AD33: =MIN(100,IF(H33="Enterprise",30,IF(H33="Mid-Market",22,14))+IF(T33="Enterprise",25,IF(T33="Mid-Market",18,10))+IF(Q33="Referral",25,IF(Q33="Organic Search",20,IF(Q33="Email",18,14)))+IF(G33="Technology",10,5)) -> 67 | AE33: =IF(U33<>"Open",U33,IF(N33>=0.8,"Commit",IF(N33>=0.5,"Best Case","Pipeline"))) -> Commit
A34: L00033 | B34: 45810 | C34: Duy Pham | D34: South | E34: SEM - Google | F34: CRM-PRO | G34: Manufacturing | H34: SMB | I34: Closed Lost | J34: 45864 | K34: 45864 | L34: 12600 | M34: 0 | N34: 0 | O34: Timing | P34: 3 | Q34: =IFERROR(VLOOKUP(E34,Lookups!$A$5:$B$24,2,FALSE),"Other") -> Paid Search | R34: =IFERROR(VLOOKUP(F34,Lookups!$D$5:$F$10,2,FALSE),"Unknown Product") -> NexaCRM Pro | S34: =IFERROR(VLOOKUP(F34,Lookups!$D$5:$F$10,3,FALSE),"Unknown") -> CRM | T34: =IF(L34>=50000,"Enterprise",IF(L34>=20000,"Mid-Market","SMB")) -> SMB | U34: =IF(I34="Closed Won","Won",IF(I34="Closed Lost","Lost","Open")) -> Lost | V34: =IF(U34="Won",L34*(1-M34),0) -> 0 | W34: =IF(U34="Open",L34*N34,0) -> 0 | X34: =IF(U34="Open","",IFERROR(K34-B34,"")) -> 54 | Y34: =IF(U34="Open",Lookups!$B$2-B34,X34) -> 54 | Z34: =IF(AND(U34="Open",Y34>30),"STALE","OK") -> OK | AA34: =TEXT(B34,"yyyy-mm") -> 2025-06 | AB34: =IF(K34="","",TEXT(K34,"yyyy-mm")) -> 2025-07 | AC34: ="Q"&ROUNDUP(MONTH(B34)/3,0)&"-"&YEAR(B34) -> Q2-2025 | AD34: =MIN(100,IF(H34="Enterprise",30,IF(H34="Mid-Market",22,14))+IF(T34="Enterprise",25,IF(T34="Mid-Market",18,10))+IF(Q34="Referral",25,IF(Q34="Organic Search",20,IF(Q34="Email",18,14)))+IF(G34="Technology",10,5)) -> 43 | AE34: =IF(U34<>"Open",U34,IF(N34>=0.8,"Commit",IF(N34>=0.5,"Best Case","Pipeline"))) -> Lost
A35: L00034 | B35: 45773 | C35: An Nguyen | D35: South | E35: Referral | F35: REV-OPS | G35: Professional Services | H35: Mid-Market | I35: Closed Lost | J35: 45801 | K35: 45801 | L35: 48900 | M35: 0 | N35: 0 | O35: No Decision | P35: 4 | Q35: =IFERROR(VLOOKUP(E35,Lookups!$A$5:$B$24,2,FALSE),"Other") -> Referral | R35: =IFERROR(VLOOKUP(F35,Lookups!$D$5:$F$10,2,FALSE),"Unknown Product") -> Revenue Operations Suite | S35: =IFERROR(VLOOKUP(F35,Lookups!$D$5:$F$10,3,FALSE),"Unknown") -> Revenue Ops | T35: =IF(L35>=50000,"Enterprise",IF(L35>=20000,"Mid-Market","SMB")) -> Mid-Market | U35: =IF(I35="Closed Won","Won",IF(I35="Closed Lost","Lost","Open")) -> Lost | V35: =IF(U35="Won",L35*(1-M35),0) -> 0 | W35: =IF(U35="Open",L35*N35,0) -> 0 | X35: =IF(U35="Open","",IFERROR(K35-B35,"")) -> 28 | Y35: =IF(U35="Open",Lookups!$B$2-B35,X35) -> 28 | Z35: =IF(AND(U35="Open",Y35>30),"STALE","OK") -> OK | AA35: =TEXT(B35,"yyyy-mm") -> 2025-04 | AB35: =IF(K35="","",TEXT(K35,"yyyy-mm")) -> 2025-05 | AC35: ="Q"&ROUNDUP(MONTH(B35)/3,0)&"-"&YEAR(B35) -> Q2-2025 | AD35: =MIN(100,IF(H35="Enterprise",30,IF(H35="Mid-Market",22,14))+IF(T35="Enterprise",25,IF(T35="Mid-Market",18,10))+IF(Q35="Referral",25,IF(Q35="Organic Search",20,IF(Q35="Email",18,14)))+IF(G35="Technology",10,5)) -> 70 | AE35: =IF(U35<>"Open",U35,IF(N35>=0.8,"Commit",IF(N35>=0.5,"Best Case","Pipeline"))) -> Lost
A36: L00035 | B36: 45912 | C36: Duy Pham | D36: South | E36: customer referral | F36: MKT-AUTO | G36: Retail | H36: SMB | I36: Closed Won | J36: 45956 | K36: 45956 | L36: 12800 | M36: 0.08 | N36: 1 | P36: 6 | Q36: =IFERROR(VLOOKUP(E36,Lookups!$A$5:$B$24,2,FALSE),"Other") -> Referral | R36: =IFERROR(VLOOKUP(F36,Lookups!$D$5:$F$10,2,FALSE),"Unknown Product") -> Marketing Automation | S36: =IFERROR(VLOOKUP(F36,Lookups!$D$5:$F$10,3,FALSE),"Unknown") -> Marketing | T36: =IF(L36>=50000,"Enterprise",IF(L36>=20000,"Mid-Market","SMB")) -> SMB | U36: =IF(I36="Closed Won","Won",IF(I36="Closed Lost","Lost","Open")) -> Won | V36: =IF(U36="Won",L36*(1-M36),0) -> 11776 | W36: =IF(U36="Open",L36*N36,0) -> 0 | X36: =IF(U36="Open","",IFERROR(K36-B36,"")) -> 44 | Y36: =IF(U36="Open",Lookups!$B$2-B36,X36) -> 44 | Z36: =IF(AND(U36="Open",Y36>30),"STALE","OK") -> OK | AA36: =TEXT(B36,"yyyy-mm") -> 2025-09 | AB36: =IF(K36="","",TEXT(K36,"yyyy-mm")) -> 2025-10 | AC36: ="Q"&ROUNDUP(MONTH(B36)/3,0)&"-"&YEAR(B36) -> Q3-2025 | AD36: =MIN(100,IF(H36="Enterprise",30,IF(H36="Mid-Market",22,14))+IF(T36="Enterprise",25,IF(T36="Mid-Market",18,10))+IF(Q36="Referral",25,IF(Q36="Organic Search",20,IF(Q36="Email",18,14)))+IF(G36="Technology",10,5)) -> 54 | AE36: =IF(U36<>"Open",U36,IF(N36>=0.8,"Commit",IF(N36>=0.5,"Best Case","Pipeline"))) -> Won
A37: L00036 | B37: 45932 | C37: An Nguyen | D37: South | E37: Conference Scan | F37: BI-PLUS | G37: Retail | H37: Mid-Market | I37: Closed Won | J37: 45944 | K37: 45944 | L37: 43600 | M37: 0.03 | N37: 1 | P37: 6 | Q37: =IFERROR(VLOOKUP(E37,Lookups!$A$5:$B$24,2,FALSE),"Other") -> Other | R37: =IFERROR(VLOOKUP(F37,Lookups!$D$5:$F$10,2,FALSE),"Unknown Product") -> Analytics Plus | S37: =IFERROR(VLOOKUP(F37,Lookups!$D$5:$F$10,3,FALSE),"Unknown") -> Analytics | T37: =IF(L37>=50000,"Enterprise",IF(L37>=20000,"Mid-Market","SMB")) -> Mid-Market | U37: =IF(I37="Closed Won","Won",IF(I37="Closed Lost","Lost","Open")) -> Won | V37: =IF(U37="Won",L37*(1-M37),0) -> 42292 | W37: =IF(U37="Open",L37*N37,0) -> 0 | X37: =IF(U37="Open","",IFERROR(K37-B37,"")) -> 12 | Y37: =IF(U37="Open",Lookups!$B$2-B37,X37) -> 12 | Z37: =IF(AND(U37="Open",Y37>30),"STALE","OK") -> OK | AA37: =TEXT(B37,"yyyy-mm") -> 2025-10 | AB37: =IF(K37="","",TEXT(K37,"yyyy-mm")) -> 2025-10 | AC37: ="Q"&ROUNDUP(MONTH(B37)/3,0)&"-"&YEAR(B37) -> Q4-2025 | AD37: =MIN(100,IF(H37="Enterprise",30,IF(H37="Mid-Market",22,14))+IF(T37="Enterprise",25,IF(T37="Mid-Market",18,10))+IF(Q37="Referral",25,IF(Q37="Organic Search",20,IF(Q37="Email",18,14)))+IF(G37="Technology",10,5)) -> 59 | AE37: =IF(U37<>"Open",U37,IF(N37>=0.8,"Commit",IF(N37>=0.5,"Best Case","Pipeline"))) -> Won
A38: L00037 | B38: 46070 | C38: Quynh Vu | D38: North | E38: Google Ads | F38: MKT-AUTO | G38: Manufacturing | H38: Mid-Market | I38: Negotiation | J38: 46201 | L38: 36600 | M38: 0.05 | N38: 0.85 | P38: 5 | Q38: =IFERROR(VLOOKUP(E38,Lookups!$A$5:$B$24,2,FALSE),"Other") -> Paid Search | R38: =IFERROR(VLOOKUP(F38,Lookups!$D$5:$F$10,2,FALSE),"Unknown Product") -> Marketing Automation | S38: =IFERROR(VLOOKUP(F38,Lookups!$D$5:$F$10,3,FALSE),"Unknown") -> Marketing | T38: =IF(L38>=50000,"Enterprise",IF(L38>=20000,"Mid-Market","SMB")) -> Mid-Market | U38: =IF(I38="Closed Won","Won",IF(I38="Closed Lost","Lost","Open")) -> Open | V38: =IF(U38="Won",L38*(1-M38),0) -> 0 | W38: =IF(U38="Open",L38*N38,0) -> 31110 | X38: =IF(U38="Open","",IFERROR(K38-B38,"")) | Y38: =IF(U38="Open",Lookups!$B$2-B38,X38) -> 196 | Z38: =IF(AND(U38="Open",Y38>30),"STALE","OK") -> STALE | AA38: =TEXT(B38,"yyyy-mm") -> 2026-02 | AB38: =IF(K38="","",TEXT(K38,"yyyy-mm")) | AC38: ="Q"&ROUNDUP(MONTH(B38)/3,0)&"-"&YEAR(B38) -> Q1-2026 | AD38: =MIN(100,IF(H38="Enterprise",30,IF(H38="Mid-Market",22,14))+IF(T38="Enterprise",25,IF(T38="Mid-Market",18,10))+IF(Q38="Referral",25,IF(Q38="Organic Search",20,IF(Q38="Email",18,14)))+IF(G38="Technology",10,5)) -> 59 | AE38: =IF(U38<>"Open",U38,IF(N38>=0.8,"Commit",IF(N38>=0.5,"Best Case","Pipeline"))) -> Commit
A39: L00038 | B39: 46149 | C39: Tuan Bui | D39: Central | E39: customer referral | F39: CRM-CORE | G39: Healthcare | H39: Mid-Market | I39: Closed Lost | J39: 46210 | K39: 46210 | L39: 10800 | M39: 0 | N39: 0 | O39: No Decision | P39: 5 | Q39: =IFERROR(VLOOKUP(E39,Lookups!$A$5:$B$24,2,FALSE),"Other") -> Referral | R39: =IFERROR(VLOOKUP(F39,Lookups!$D$5:$F$10,2,FALSE),"Unknown Product") -> NexaCRM Core | S39: =IFERROR(VLOOKUP(F39,Lookups!$D$5:$F$10,3,FALSE),"Unknown") -> CRM | T39: =IF(L39>=50000,"Enterprise",IF(L39>=20000,"Mid-Market","SMB")) -> SMB | U39: =IF(I39="Closed Won","Won",IF(I39="Closed Lost","Lost","Open")) -> Lost | V39: =IF(U39="Won",L39*(1-M39),0) -> 0 | W39: =IF(U39="Open",L39*N39,0) -> 0 | X39: =IF(U39="Open","",IFERROR(K39-B39,"")) -> 61 | Y39: =IF(U39="Open",Lookups!$B$2-B39,X39) -> 61 | Z39: =IF(AND(U39="Open",Y39>30),"STALE","OK") -> OK | AA39: =TEXT(B39,"yyyy-mm") -> 2026-05 | AB39: =IF(K39="","",TEXT(K39,"yyyy-mm")) -> 2026-07 | AC39: ="Q"&ROUNDUP(MONTH(B39)/3,0)&"-"&YEAR(B39) -> Q2-2026 | AD39: =MIN(100,IF(H39="Enterprise",30,IF(H39="Mid-Market",22,14))+IF(T39="Enterprise",25,IF(T39="Mid-Market",18,10))+IF(Q39="Referral",25,IF(Q39="Organic Search",20,IF(Q39="Email",18,14)))+IF(G39="Technology",10,5)) -> 62 | AE39: =IF(U39<>"Open",U39,IF(N39>=0.8,"Commit",IF(N39>=0.5,"Best Case","Pipeline"))) -> Lost
A40: L00039 | B40: 45962 | C40: An Nguyen | D40: South | E40: LI Ads | F40: CRM-CORE | G40: Manufacturing | H40: SMB | I40: Closed Lost | J40: 45996 | K40: 45996 | L40: 4700 | M40: 0 | N40: 0 | O40: No Decision | P40: 4 | Q40: =IFERROR(VLOOKUP(E40,Lookups!$A$5:$B$24,2,FALSE),"Other") -> LinkedIn | R40: =IFERROR(VLOOKUP(F40,Lookups!$D$5:$F$10,2,FALSE),"Unknown Product") -> NexaCRM Core | S40: =IFERROR(VLOOKUP(F40,Lookups!$D$5:$F$10,3,FALSE),"Unknown") -> CRM | T40: =IF(L40>=50000,"Enterprise",IF(L40>=20000,"Mid-Market","SMB")) -> SMB | U40: =IF(I40="Closed Won","Won",IF(I40="Closed Lost","Lost","Open")) -> Lost | V40: =IF(U40="Won",L40*(1-M40),0) -> 0 | W40: =IF(U40="Open",L40*N40,0) -> 0 | X40: =IF(U40="Open","",IFERROR(K40-B40,"")) -> 34 | Y40: =IF(U40="Open",Lookups!$B$2-B40,X40) -> 34 | Z40: =IF(AND(U40="Open",Y40>30),"STALE","OK") -> OK | AA40: =TEXT(B40,"yyyy-mm") -> 2025-11 | AB40: =IF(K40="","",TEXT(K40,"yyyy-mm")) -> 2025-12 | AC40: ="Q"&ROUNDUP(MONTH(B40)/3,0)&"-"&YEAR(B40) -> Q4-2025 | AD40: =MIN(100,IF(H40="Enterprise",30,IF(H40="Mid-Market",22,14))+IF(T40="Enterprise",25,IF(T40="Mid-Market",18,10))+IF(Q40="Referral",25,IF(Q40="Organic Search",20,IF(Q40="Email",18,14)))+IF(G40="Technology",10,5)) -> 43 | AE40: =IF(U40<>"Open",U40,IF(N40>=0.8,"Commit",IF(N40>=0.5,"Best Case","Pipeline"))) -> Lost
...

Sheet Rep_Performance
A1: Rep | B1: Region | C1: Team | D1: Total Leads | E1: Won Deals | F1: Lost Deals | G1: Win Rate | H1: Won Revenue | I1: Open Pipeline | J1: Weighted Pipeline | K1: Avg Sales Cycle | L1: Revenue Target | M1: Target Attainment
A2: An Nguyen | B2: =IFERROR(VLOOKUP(A2,Lookups!$I$5:$L$12,2,FALSE),"") -> South | C2: =IFERROR(VLOOKUP(A2,Lookups!$I$5:$L$12,3,FALSE),"") -> Growth | D2: =COUNTIF(CRM_Data!$C$2:$C$1801,A2) -> 218 | E2: =COUNTIFS(CRM_Data!$C$2:$C$1801,A2,CRM_Data!$U$2:$U$1801,"Won") -> 41 | F2: =COUNTIFS(CRM_Data!$C$2:$C$1801,A2,CRM_Data!$U$2:$U$1801,"Lost") -> 125 | G2: =IFERROR(E2/(E2+F2),0) -> 0.24698795 | H2: =SUMIFS(CRM_Data!$V$2:$V$1801,CRM_Data!$C$2:$C$1801,A2) -> 1014864 | I2: =SUMIFS(CRM_Data!$L$2:$L$1801,CRM_Data!$C$2:$C$1801,A2,CRM_Data!$U$2:$U$1801,"Open") -> 1690200 | J2: =SUMIFS(CRM_Data!$W$2:$W$1801,CRM_Data!$C$2:$C$1801,A2) -> 1077505 | K2: =IFERROR(SUMIFS(CRM_Data!$X$2:$X$1801,CRM_Data!$C$2:$C$1801,A2,CRM_Data!$U$2:$U$1801,"Won")/E2,0) -> 51.97561 | L2: =IFERROR(VLOOKUP(A2,Lookups!$I$5:$L$12,4,FALSE),0) -> 1035000 | M2: =IFERROR(H2/L2,0) -> 0.98054493
A3: Bao Tran | B3: =IFERROR(VLOOKUP(A3,Lookups!$I$5:$L$12,2,FALSE),"") -> South | C3: =IFERROR(VLOOKUP(A3,Lookups!$I$5:$L$12,3,FALSE),"") -> Growth | D3: =COUNTIF(CRM_Data!$C$2:$C$1801,A3) -> 237 | E3: =COUNTIFS(CRM_Data!$C$2:$C$1801,A3,CRM_Data!$U$2:$U$1801,"Won") -> 56 | F3: =COUNTIFS(CRM_Data!$C$2:$C$1801,A3,CRM_Data!$U$2:$U$1801,"Lost") -> 131 | G3: =IFERROR(E3/(E3+F3),0) -> 0.29946524 | H3: =SUMIFS(CRM_Data!$V$2:$V$1801,CRM_Data!$C$2:$C$1801,A3) -> 1296394 | I3: =SUMIFS(CRM_Data!$L$2:$L$1801,CRM_Data!$C$2:$C$1801,A3,CRM_Data!$U$2:$U$1801,"Open") -> 1582300 | J3: =SUMIFS(CRM_Data!$W$2:$W$1801,CRM_Data!$C$2:$C$1801,A3) -> 907010 | K3: =IFERROR(SUMIFS(CRM_Data!$X$2:$X$1801,CRM_Data!$C$2:$C$1801,A3,CRM_Data!$U$2:$U$1801,"Won")/E3,0) -> 52.339286 | L3: =IFERROR(VLOOKUP(A3,Lookups!$I$5:$L$12,4,FALSE),0) -> 1232000 | M3: =IFERROR(H3/L3,0) -> 1.0522679
A4: Chi Le | B4: =IFERROR(VLOOKUP(A4,Lookups!$I$5:$L$12,2,FALSE),"") -> South | C4: =IFERROR(VLOOKUP(A4,Lookups!$I$5:$L$12,3,FALSE),"") -> Commercial | D4: =COUNTIF(CRM_Data!$C$2:$C$1801,A4) -> 203 | E4: =COUNTIFS(CRM_Data!$C$2:$C$1801,A4,CRM_Data!$U$2:$U$1801,"Won") -> 38 | F4: =COUNTIFS(CRM_Data!$C$2:$C$1801,A4,CRM_Data!$U$2:$U$1801,"Lost") -> 109 | G4: =IFERROR(E4/(E4+F4),0) -> 0.2585034 | H4: =SUMIFS(CRM_Data!$V$2:$V$1801,CRM_Data!$C$2:$C$1801,A4) -> 1164807 | I4: =SUMIFS(CRM_Data!$L$2:$L$1801,CRM_Data!$C$2:$C$1801,A4,CRM_Data!$U$2:$U$1801,"Open") -> 1881700 | J4: =SUMIFS(CRM_Data!$W$2:$W$1801,CRM_Data!$C$2:$C$1801,A4) -> 1247955 | K4: =IFERROR(SUMIFS(CRM_Data!$X$2:$X$1801,CRM_Data!$C$2:$C$1801,A4,CRM_Data!$U$2:$U$1801,"Won")/E4,0) -> 55.026316 | L4: =IFERROR(VLOOKUP(A4,Lookups!$I$5:$L$12,4,FALSE),0) -> 1258000 | M4: =IFERROR(H4/L4,0) -> 0.92591971
A5: Duy Pham | B5: =IFERROR(VLOOKUP(A5,Lookups!$I$5:$L$12,2,FALSE),"") -> South | C5: =IFERROR(VLOOKUP(A5,Lookups!$I$5:$L$12,3,FALSE),"") -> Commercial | D5: =COUNTIF(CRM_Data!$C$2:$C$1801,A5) -> 222 | E5: =COUNTIFS(CRM_Data!$C$2:$C$1801,A5,CRM_Data!$U$2:$U$1801,"Won") -> 40 | F5: =COUNTIFS(CRM_Data!$C$2:$C$1801,A5,CRM_Data!$U$2:$U$1801,"Lost") -> 131 | G5: =IFERROR(E5/(E5+F5),0) -> 0.23391813 | H5: =SUMIFS(CRM_Data!$V$2:$V$1801,CRM_Data!$C$2:$C$1801,A5) -> 1187010 | I5: =SUMIFS(CRM_Data!$L$2:$L$1801,CRM_Data!$C$2:$C$1801,A5,CRM_Data!$U$2:$U$1801,"Open") -> 1879500 | J5: =SUMIFS(CRM_Data!$W$2:$W$1801,CRM_Data!$C$2:$C$1801,A5) -> 1178695 | K5: =IFERROR(SUMIFS(CRM_Data!$X$2:$X$1801,CRM_Data!$C$2:$C$1801,A5,CRM_Data!$U$2:$U$1801,"Won")/E5,0) -> 57.975 | L5: =IFERROR(VLOOKUP(A5,Lookups!$I$5:$L$12,4,FALSE),0) -> 1163000 | M5: =IFERROR(H5/L5,0) -> 1.0206449
A6: Ha Vo | B6: =IFERROR(VLOOKUP(A6,Lookups!$I$5:$L$12,2,FALSE),"") -> North | C6: =IFERROR(VLOOKUP(A6,Lookups!$I$5:$L$12,3,FALSE),"") -> Growth | D6: =COUNTIF(CRM_Data!$C$2:$C$1801,A6) -> 223 | E6: =COUNTIFS(CRM_Data!$C$2:$C$1801,A6,CRM_Data!$U$2:$U$1801,"Won") -> 42 | F6: =COUNTIFS(CRM_Data!$C$2:$C$1801,A6,CRM_Data!$U$2:$U$1801,"Lost") -> 130 | G6: =IFERROR(E6/(E6+F6),0) -> 0.24418605 | H6: =SUMIFS(CRM_Data!$V$2:$V$1801,CRM_Data!$C$2:$C$1801,A6) -> 1007131 | I6: =SUMIFS(CRM_Data!$L$2:$L$1801,CRM_Data!$C$2:$C$1801,A6,CRM_Data!$U$2:$U$1801,"Open") -> 1397100 | J6: =SUMIFS(CRM_Data!$W$2:$W$1801,CRM_Data!$C$2:$C$1801,A6) -> 747545 | K6: =IFERROR(SUMIFS(CRM_Data!$X$2:$X$1801,CRM_Data!$C$2:$C$1801,A6,CRM_Data!$U$2:$U$1801,"Won")/E6,0) -> 60.166667 | L6: =IFERROR(VLOOKUP(A6,Lookups!$I$5:$L$12,4,FALSE),0) -> 1057000 | M6: =IFERROR(H6/L6,0) -> 0.95282025
A7: Minh Do | B7: =IFERROR(VLOOKUP(A7,Lookups!$I$5:$L$12,2,FALSE),"") -> North | C7: =IFERROR(VLOOKUP(A7,Lookups!$I$5:$L$12,3,FALSE),"") -> Commercial | D7: =COUNTIF(CRM_Data!$C$2:$C$1801,A7) -> 236 | E7: =COUNTIFS(CRM_Data!$C$2:$C$1801,A7,CRM_Data!$U$2:$U$1801,"Won") -> 45 | F7: =COUNTIFS(CRM_Data!$C$2:$C$1801,A7,CRM_Data!$U$2:$U$1801,"Lost") -> 146 | G7: =IFERROR(E7/(E7+F7),0) -> 0.23560209 | H7: =SUMIFS(CRM_Data!$V$2:$V$1801,CRM_Data!$C$2:$C$1801,A7) -> 1168309 | I7: =SUMIFS(CRM_Data!$L$2:$L$1801,CRM_Data!$C$2:$C$1801,A7,CRM_Data!$U$2:$U$1801,"Open") -> 1454400 | J7: =SUMIFS(CRM_Data!$W$2:$W$1801,CRM_Data!$C$2:$C$1801,A7) -> 926075 | K7: =IFERROR(SUMIFS(CRM_Data!$X$2:$X$1801,CRM_Data!$C$2:$C$1801,A7,CRM_Data!$U$2:$U$1801,"Won")/E7,0) -> 49.066667 | L7: =IFERROR(VLOOKUP(A7,Lookups!$I$5:$L$12,4,FALSE),0) -> 1075000 | M7: =IFERROR(H7/L7,0) -> 1.0867991
A8: Quynh Vu | B8: =IFERROR(VLOOKUP(A8,Lookups!$I$5:$L$12,2,FALSE),"") -> North | C8: =IFERROR(VLOOKUP(A8,Lookups!$I$5:$L$12,3,FALSE),"") -> Growth | D8: =COUNTIF(CRM_Data!$C$2:$C$1801,A8) -> 226 | E8: =COUNTIFS(CRM_Data!$C$2:$C$1801,A8,CRM_Data!$U$2:$U$1801,"Won") -> 49 | F8: =COUNTIFS(CRM_Data!$C$2:$C$1801,A8,CRM_Data!$U$2:$U$1801,"Lost") -> 117 | G8: =IFERROR(E8/(E8+F8),0) -> 0.29518072 | H8: =SUMIFS(CRM_Data!$V$2:$V$1801,CRM_Data!$C$2:$C$1801,A8) -> 1594527 | I8: =SUMIFS(CRM_Data!$L$2:$L$1801,CRM_Data!$C$2:$C$1801,A8,CRM_Data!$U$2:$U$1801,"Open") -> 1614800 | J8: =SUMIFS(CRM_Data!$W$2:$W$1801,CRM_Data!$C$2:$C$1801,A8) -> 884890 | K8: =IFERROR(SUMIFS(CRM_Data!$X$2:$X$1801,CRM_Data!$C$2:$C$1801,A8,CRM_Data!$U$2:$U$1801,"Won")/E8,0) -> 60.285714 | L8: =IFERROR(VLOOKUP(A8,Lookups!$I$5:$L$12,4,FALSE),0) -> 1754000 | M8: =IFERROR(H8/L8,0) -> 0.90908039
A9: Tuan Bui | B9: =IFERROR(VLOOKUP(A9,Lookups!$I$5:$L$12,2,FALSE),"") -> Central | C9: =IFERROR(VLOOKUP(A9,Lookups!$I$5:$L$12,3,FALSE),"") -> Commercial | D9: =COUNTIF(CRM_Data!$C$2:$C$1801,A9) -> 235 | E9: =COUNTIFS(CRM_Data!$C$2:$C$1801,A9,CRM_Data!$U$2:$U$1801,"Won") -> 50 | F9: =COUNTIFS(CRM_Data!$C$2:$C$1801,A9,CRM_Data!$U$2:$U$1801,"Lost") -> 136 | G9: =IFERROR(E9/(E9+F9),0) -> 0.2688172 | H9: =SUMIFS(CRM_Data!$V$2:$V$1801,CRM_Data!$C$2:$C$1801,A9) -> 1342588 | I9: =SUMIFS(CRM_Data!$L$2:$L$1801,CRM_Data!$C$2:$C$1801,A9,CRM_Data!$U$2:$U$1801,"Open") -> 1511200 | J9: =SUMIFS(CRM_Data!$W$2:$W$1801,CRM_Data!$C$2:$C$1801,A9) -> 860340 | K9: =IFERROR(SUMIFS(CRM_Data!$X$2:$X$1801,CRM_Data!$C$2:$C$1801,A9,CRM_Data!$U$2:$U$1801,"Won")/E9,0) -> 55.02 | L9: =IFERROR(VLOOKUP(A9,Lookups!$I$5:$L$12,4,FALSE),0) -> 1289000 | M9: =IFERROR(H9/L9,0) -> 1.0415733

